<?xml version="1.0"?>
<robot name="carmodel">

  <material name="white">
    <color rgba="1 1 1 1"/>
  </material>
  <material name="black">
    <color rgba="0 0 0 1"/>
  </material>
  <material name="blue">
    <color rgba="0 0 0.8 1"/>
  </material>

  <link name="base_link">
    <visual>
      <geometry>
        <mesh
          filename="package://carmodel_description/meshes/Bodys.STL" />
      </geometry>
        <origin rpy="1.5705 0 0" xyz="-0.25 0.1675 -0.0075"/>
      <material name="white"/>
    </visual>
    <collision>
      <geometry>
        <box size="0.5 0.3 0.07"/>
      </geometry>
      <origin rpy="0 0 0" xyz="0 0 0.035"/>
    </collision>
    <inertial>
      <origin xyz="-0.00509 0 0.03461" rpy="0 0 0"/>
      <mass value="32"/>
      <inertia
        ixx="28.711604" ixy="0.0" ixz="0.0"
        iyy="92.409218" iyz="0.0"
        izz="69.233565"/>
    </inertial>
  </link>

  <link name="wheel_1">
    <visual>
      <geometry>
        <mesh
          filename="package://carmodel_description/meshes/Wheel.STL" />
      </geometry>
      <origin rpy="1.5705 0 0" xyz="-0.055 0 -0.055 "/>
      <material name="black"/>
    </visual>
    <collision>
      <geometry>
        <cylinder length="0.015" radius="0.055"/>
      </geometry>
      <origin rpy="1.5705 0 0" xyz="0 -0.0075 0"/>
    </collision>
    <inertial>
      <origin xyz="0 -0.0075 0" rpy="0 0 0"/>
      <mass value="1.0252"/>
      <inertia
        ixx="0.09065214" ixy="0.0" ixz="0.0"
        iyy="0.09065214" iyz="0.0"
        izz="0.17745989"/>
    </inertial>
  </link> 

    <link name="wheel_2">
    <visual>
      <geometry>
        <mesh
          filename="package://carmodel_description/meshes/Wheel.STL" />
      </geometry>
      <origin rpy="1.5705 0 0" xyz="-0.055 0 -0.055"/>
      <material name="white"/>
    </visual>
    <collision>
      <geometry>
        <cylinder length="0.015" radius="0.055"/>
      </geometry>
      <origin rpy="1.5705 0 0" xyz="0 -0.0075 0"/>
    </collision>
    <inertial>
      <origin xyz="0 -0.0075 0" rpy="0 0 0"/>
      <mass value="1.252"/>
      <inertia
        ixx="0.09065214" ixy="0.0" ixz="0.0"
        iyy="0.09065214" iyz="0.0"
        izz="0.17745989"/>
    </inertial>
  </link> 

    <link name="wheel_3">
    <visual>
      <geometry>
        <mesh
          filename="package://carmodel_description/meshes/Wheel.STL" />
      </geometry>
      <origin rpy="1.5705 0 0" xyz="-0.055 0 -0.055"/>
      <material name="white"/>
    </visual>
    <collision>
      <geometry>
        <cylinder length="0.015" radius="0.055"/>
      </geometry>
      <origin rpy="1.5705 0 0" xyz="0 -0.0075 0"/>
    </collision>
    <inertial>
      <origin xyz="0 -0.0075 0" rpy="0 0 0"/>
      <mass value="1.252"/>
      <inertia
        ixx="0.09065214" ixy="0.0" ixz="0.0"
        iyy="0.09065214" iyz="0.0"
        izz="0.17745989"/>
    </inertial>
  </link> 

    <link name="wheel_4">
    <visual>
      <geometry>
        <mesh
          filename="package://carmodel_description/meshes/Wheel.STL" />
      </geometry>
      <origin rpy="1.5705 0 0" xyz="-0.055 0 -0.055"/>
      <material name="white"/>
    </visual>
    <collision>
      <geometry>
        <cylinder length="0.015" radius="0.055"/>
      </geometry>
      <origin rpy="1.5705 0 0" xyz="0 -0.0075 0"/>
    </collision>
    <inertial>
      <origin xyz="0 -0.0075 0" rpy="0 0 0"/>
      <mass value="1.252"/>
      <inertia
        ixx="0.09065214" ixy="0.0" ixz="0.0"
        iyy="0.09065214" iyz="0.0"
        izz="0.17745989"/>
    </inertial>
  </link> 

  <link name="odom"/>

  <joint name="base_odom" type="fixed">
    <origin xyz="0 0 0.5" rpy="0 0 0" />
    <parent link="base_link" />
    <child  link="odom" />
  </joint>

  <joint name="joint_base_wheel1" type="continuous">
    <origin rpy="0 0 0" xyz="0.13189 -0.1525 0.03018 "/>
    <axis rpy="0 0 0" xyz="0 1 0"/>
    <parent link="base_link"/>
    <child link="wheel_1"/>
        <limit effort="500" velocity="500"/>  
        <joint_properties damping="0.0" friction="0.0"/>
  </joint>

  <joint name="joint_base_wheel2" type="continuous">
    <origin rpy="0 0 0" xyz="-0.13211 -0.1525 0.03018 "/>
    <axis rpy="0 0 0" xyz="0 1 0"/>
    <parent link="base_link"/>
    <child link="wheel_2"/>
        <limit effort="500" velocity="500"/>  
        <joint_properties damping="0.0" friction="0.0"/>
  </joint>

  <joint name="joint_base_wheel3" type="continuous">
    <origin rpy="0 0 0" xyz="0.13189 0.1675 0.03018 "/>
    <axis rpy="0 0 0" xyz="0 1 0"/>
    <parent link="base_link"/>
    <child link="wheel_3"/>
        <limit effort="500" velocity="500"/>  
        <joint_properties damping="0.0" friction="0.0"/>
  </joint>

  <joint name="joint_base_wheel4" type="continuous">
    <origin rpy="0 0 0" xyz="-0.13211 0.1675 0.03018 "/>
    <axis rpy="0 0 0" xyz="0 1 0"/>
    <parent link="base_link"/>
    <child link="wheel_4"/>
        <limit effort="500" velocity="500"/>  
        <joint_properties damping="0.0" friction="0.0"/>
  </joint>

    <!-- transmission
    <transmission name="wheel1_trans">
      <type>transmission_interface/SimpleTransmission</type>
      <actuator name="wheel1_motor">
        <mechanicalReduction>1</mechanicalReduction>
      </actuator>
      <joint name="joint_base_wheel1">
        <hardwareInterface>hardware_interface/VelocityJointInterface</hardwareInterface>
      </joint>
    </transmission>

    <transmission name="wheel2_trans">
      <type>transmission_interface/SimpleTransmission</type>
      <actuator name="wheel2_motor">
        <mechanicalReduction>1</mechanicalReduction>
      </actuator>
      <joint name="joint_base_wheel2">
        <hardwareInterface>hardware_interface/VelocityJointInterface</hardwareInterface>
      </joint>
    </transmission>

    <transmission name="wheel3_trans">
      <type>transmission_interface/SimpleTransmission</type>
      <actuator name="wheel3_motor">
        <mechanicalReduction>1</mechanicalReduction>
      </actuator>
      <joint name="joint_base_wheel3">
        <hardwareInterface>hardware_interface/VelocityJointInterface</hardwareInterface>
      </joint>
    </transmission>

    <transmission name="wheel4_trans">
      <type>transmission_interface/SimpleTransmission</type>
      <actuator name="wheel4_motor">
        <mechanicalReduction>1</mechanicalReduction>
      </actuator>
      <joint name="joint_base_wheel4">
        <hardwareInterface>hardware_interface/VelocityJointInterface</hardwareInterface>
      </joint>
    </transmission>
    -->

</robot>
